# py_try_exception